2025-04-20 18:33:24,688 - INFO - Информация о боте отправлена green_ruff, chat_id: 1230795197
2025-04-20 18:33:36,945 - ERROR - Infinity polling: polling exited
2025-04-20 18:33:36,946 - ERROR - Break infinity polling
2025-04-20 18:41:05,747 - INFO - Уаедомление отправлено пользователю 1230795197 о событии Event21
2025-04-20 18:41:22,774 - ERROR - Infinity polling: polling exited
2025-04-20 18:41:22,775 - ERROR - Break infinity polling
2025-04-20 18:52:57,430 - ERROR - Ошибка при обработке id от пользователя green_ruff, chat_id: 1230795197. Ошибка: Id должен быть цифрой или числом!!!2025-04-20 18:56:25,014 - ERROR - Infinity polling: polling exited
2025-04-20 18:56:25,014 - ERROR - Break infinity polling
2025-04-20 18:56:54,377 - ERROR - Ошибка при вводе времени от пользователя green_ruff, chat_id: 1230795197. Введенное время: ываы
2025-04-20 18:57:31,356 - ERROR - Ошибка при вводе даты от пользователя green_ruff, chat_id: 1230795197. Введенная дата: аццуауц
2025-04-20 18:57:31,698 - ERROR - Ошибка при добавлении мероприятия для пользователя 1230795197: 'datetime'
2025-04-20 19:01:45,525 - ERROR - Ошибка при добавлении мероприятия для пользователя 1230795197: duplicate key value violates unique constraint "events_pkey"
DETAIL:  Key (e_id)=(21) already exists.

2025-04-20 19:02:45,393 - INFO - Пользователем 1230795197 было создано мероприятие Event22
2025-04-20 19:02:54,318 - ERROR - Infinity polling: polling exited
2025-04-20 19:02:54,319 - ERROR - Break infinity polling
2025-04-20 19:04:54,229 - INFO - Информация о количестве мероприятий отправлена пользователю green_ruff
2025-04-20 19:05:01,685 - ERROR - Infinity polling: polling exited
2025-04-20 19:05:01,685 - ERROR - Break infinity polling
2025-04-29 16:11:19,839 - ERROR - Infinity polling: polling exited
2025-04-29 16:11:19,842 - ERROR - Break infinity polling
2025-04-29 16:14:37,063 - ERROR - Infinity polling exception: HTTPSConnectionPool(host='api.telegram.org', port=443): Read timed out. (read timeout=25)
2025-04-29 16:14:37,066 - ERROR - Exception traceback:
Traceback (most recent call last):
  File "/Users/shekspii/Desktop/OOP_Global/labs/lb_2_OOP/projectX/myenv/lib/python3.13/site-packages/urllib3/connectionpool.py", line 534, in _make_request
    response = conn.getresponse()
  File "/Users/shekspii/Desktop/OOP_Global/labs/lb_2_OOP/projectX/myenv/lib/python3.13/site-packages/urllib3/connection.py", line 516, in getresponse
    httplib_response = super().getresponse()
  File "/opt/homebrew/Cellar/python@3.13/3.13.2/Frameworks/Python.framework/Versions/3.13/lib/python3.13/http/client.py", line 1430, in getresponse
    response.begin()
    ~~~~~~~~~~~~~~^^
  File "/opt/homebrew/Cellar/python@3.13/3.13.2/Frameworks/Python.framework/Versions/3.13/lib/python3.13/http/client.py", line 331, in begin
    version, status, reason = self._read_status()
                              ~~~~~~~~~~~~~~~~~^^
  File "/opt/homebrew/Cellar/python@3.13/3.13.2/Frameworks/Python.framework/Versions/3.13/lib/python3.13/http/client.py", line 292, in _read_status
    line = str(self.fp.readline(_MAXLINE + 1), "iso-8859-1")
               ~~~~~~~~~~~~~~~~^^^^^^^^^^^^^^
  File "/opt/homebrew/Cellar/python@3.13/3.13.2/Frameworks/Python.framework/Versions/3.13/lib/python3.13/socket.py", line 719, in readinto
    return self._sock.recv_into(b)
           ~~~~~~~~~~~~~~~~~~~~^^^
  File "/opt/homebrew/Cellar/python@3.13/3.13.2/Frameworks/Python.framework/Versions/3.13/lib/python3.13/ssl.py", line 1304, in recv_into
    return self.read(nbytes, buffer)
           ~~~~~~~~~^^^^^^^^^^^^^^^^
  File "/opt/homebrew/Cellar/python@3.13/3.13.2/Frameworks/Python.framework/Versions/3.13/lib/python3.13/ssl.py", line 1138, in read
    return self._sslobj.read(len, buffer)
           ~~~~~~~~~~~~~~~~~^^^^^^^^^^^^^
TimeoutError: The read operation timed out

The above exception was the direct cause of the following exception:

Traceback (most recent call last):
  File "/Users/shekspii/Desktop/OOP_Global/labs/lb_2_OOP/projectX/myenv/lib/python3.13/site-packages/requests/adapters.py", line 667, in send
    resp = conn.urlopen(
        method=request.method,
    ...<9 lines>...
        chunked=chunked,
    )
  File "/Users/shekspii/Desktop/OOP_Global/labs/lb_2_OOP/projectX/myenv/lib/python3.13/site-packages/urllib3/connectionpool.py", line 841, in urlopen
    retries = retries.increment(
        method, url, error=new_e, _pool=self, _stacktrace=sys.exc_info()[2]
    )
  File "/Users/shekspii/Desktop/OOP_Global/labs/lb_2_OOP/projectX/myenv/lib/python3.13/site-packages/urllib3/util/retry.py", line 474, in increment
    raise reraise(type(error), error, _stacktrace)
          ~~~~~~~^^^^^^^^^^^^^^^^^^^^^^^^^^^^^^^^^
  File "/Users/shekspii/Desktop/OOP_Global/labs/lb_2_OOP/projectX/myenv/lib/python3.13/site-packages/urllib3/util/util.py", line 39, in reraise
    raise value
  File "/Users/shekspii/Desktop/OOP_Global/labs/lb_2_OOP/projectX/myenv/lib/python3.13/site-packages/urllib3/connectionpool.py", line 787, in urlopen
    response = self._make_request(
        conn,
    ...<10 lines>...
        **response_kw,
    )
  File "/Users/shekspii/Desktop/OOP_Global/labs/lb_2_OOP/projectX/myenv/lib/python3.13/site-packages/urllib3/connectionpool.py", line 536, in _make_request
    self._raise_timeout(err=e, url=url, timeout_value=read_timeout)
    ~~~~~~~~~~~~~~~~~~~^^^^^^^^^^^^^^^^^^^^^^^^^^^^^^^^^^^^^^^^^^^^
  File "/Users/shekspii/Desktop/OOP_Global/labs/lb_2_OOP/projectX/myenv/lib/python3.13/site-packages/urllib3/connectionpool.py", line 367, in _raise_timeout
    raise ReadTimeoutError(
        self, url, f"Read timed out. (read timeout={timeout_value})"
    ) from err
urllib3.exceptions.ReadTimeoutError: HTTPSConnectionPool(host='api.telegram.org', port=443): Read timed out. (read timeout=25)

During handling of the above exception, another exception occurred:

Traceback (most recent call last):
  File "/Users/shekspii/Desktop/OOP_Global/labs/lb_2_OOP/projectX/myenv/lib/python3.13/site-packages/telebot/__init__.py", line 1110, in infinity_polling
    self.polling(non_stop=True, timeout=timeout, long_polling_timeout=long_polling_timeout,
    ~~~~~~~~~~~~^^^^^^^^^^^^^^^^^^^^^^^^^^^^^^^^^^^^^^^^^^^^^^^^^^^^^^^^^^^^^^^^^^^^^^^^^^^
                 logger_level=logger_level, allowed_updates=allowed_updates, restart_on_change=False,
                 ^^^^^^^^^^^^^^^^^^^^^^^^^^^^^^^^^^^^^^^^^^^^^^^^^^^^^^^^^^^^^^^^^^^^^^^^^^^^^^^^^^^^
                 *args, **kwargs)
                 ^^^^^^^^^^^^^^^^
  File "/Users/shekspii/Desktop/OOP_Global/labs/lb_2_OOP/projectX/myenv/lib/python3.13/site-packages/telebot/__init__.py", line 1198, in polling
    self.__threaded_polling(non_stop=non_stop, interval=interval, timeout=timeout, long_polling_timeout=long_polling_timeout,
    ~~~~~~~~~~~~~~~~~~~~~~~^^^^^^^^^^^^^^^^^^^^^^^^^^^^^^^^^^^^^^^^^^^^^^^^^^^^^^^^^^^^^^^^^^^^^^^^^^^^^^^^^^^^^^^^^^^^^^^^^^
                            logger_level=logger_level, allowed_updates=allowed_updates)
                            ^^^^^^^^^^^^^^^^^^^^^^^^^^^^^^^^^^^^^^^^^^^^^^^^^^^^^^^^^^^
  File "/Users/shekspii/Desktop/OOP_Global/labs/lb_2_OOP/projectX/myenv/lib/python3.13/site-packages/telebot/__init__.py", line 1273, in __threaded_polling
    raise e
  File "/Users/shekspii/Desktop/OOP_Global/labs/lb_2_OOP/projectX/myenv/lib/python3.13/site-packages/telebot/__init__.py", line 1234, in __threaded_polling
    polling_thread.raise_exceptions()
    ~~~~~~~~~~~~~~~~~~~~~~~~~~~~~~~^^
  File "/Users/shekspii/Desktop/OOP_Global/labs/lb_2_OOP/projectX/myenv/lib/python3.13/site-packages/telebot/util.py", line 111, in raise_exceptions
    raise self.exception_info
  File "/Users/shekspii/Desktop/OOP_Global/labs/lb_2_OOP/projectX/myenv/lib/python3.13/site-packages/telebot/util.py", line 93, in run
    task(*args, **kwargs)
    ~~~~^^^^^^^^^^^^^^^^^
  File "/Users/shekspii/Desktop/OOP_Global/labs/lb_2_OOP/projectX/myenv/lib/python3.13/site-packages/telebot/__init__.py", line 688, in __retrieve_updates
    updates = self.get_updates(offset=(self.last_update_id + 1),
                               allowed_updates=allowed_updates,
                               timeout=timeout, long_polling_timeout=long_polling_timeout)
  File "/Users/shekspii/Desktop/OOP_Global/labs/lb_2_OOP/projectX/myenv/lib/python3.13/site-packages/telebot/__init__.py", line 660, in get_updates
    json_updates = apihelper.get_updates(
        self.token, offset=offset, limit=limit, timeout=timeout, allowed_updates=allowed_updates,
        long_polling_timeout=long_polling_timeout)
  File "/Users/shekspii/Desktop/OOP_Global/labs/lb_2_OOP/projectX/myenv/lib/python3.13/site-packages/telebot/apihelper.py", line 332, in get_updates
    return _make_request(token, method_url, params=payload)
  File "/Users/shekspii/Desktop/OOP_Global/labs/lb_2_OOP/projectX/myenv/lib/python3.13/site-packages/telebot/apihelper.py", line 162, in _make_request
    result = _get_req_session().request(
        method, request_url, params=params, files=files,
        timeout=(connect_timeout, read_timeout), proxies=proxy)
  File "/Users/shekspii/Desktop/OOP_Global/labs/lb_2_OOP/projectX/myenv/lib/python3.13/site-packages/requests/sessions.py", line 589, in request
    resp = self.send(prep, **send_kwargs)
  File "/Users/shekspii/Desktop/OOP_Global/labs/lb_2_OOP/projectX/myenv/lib/python3.13/site-packages/requests/sessions.py", line 703, in send
    r = adapter.send(request, **kwargs)
  File "/Users/shekspii/Desktop/OOP_Global/labs/lb_2_OOP/projectX/myenv/lib/python3.13/site-packages/requests/adapters.py", line 713, in send
    raise ReadTimeout(e, request=request)
requests.exceptions.ReadTimeout: HTTPSConnectionPool(host='api.telegram.org', port=443): Read timed out. (read timeout=25)

2025-04-29 16:15:10,429 - ERROR - Infinity polling: polling exited
2025-04-29 16:15:10,429 - ERROR - Break infinity polling
2025-04-29 16:16:08,776 - ERROR - Infinity polling exception: HTTPSConnectionPool(host='api.telegram.org', port=443): Read timed out. (read timeout=20)
2025-04-29 16:16:08,783 - ERROR - Exception traceback:
Traceback (most recent call last):
  File "/Users/shekspii/Desktop/OOP_Global/labs/lb_2_OOP/projectX/myenv/lib/python3.13/site-packages/urllib3/connectionpool.py", line 464, in _make_request
    self._validate_conn(conn)
    ~~~~~~~~~~~~~~~~~~~^^^^^^
  File "/Users/shekspii/Desktop/OOP_Global/labs/lb_2_OOP/projectX/myenv/lib/python3.13/site-packages/urllib3/connectionpool.py", line 1093, in _validate_conn
    conn.connect()
    ~~~~~~~~~~~~^^
  File "/Users/shekspii/Desktop/OOP_Global/labs/lb_2_OOP/projectX/myenv/lib/python3.13/site-packages/urllib3/connection.py", line 741, in connect
    sock_and_verified = _ssl_wrap_socket_and_match_hostname(
        sock=sock,
    ...<14 lines>...
        assert_fingerprint=self.assert_fingerprint,
    )
  File "/Users/shekspii/Desktop/OOP_Global/labs/lb_2_OOP/projectX/myenv/lib/python3.13/site-packages/urllib3/connection.py", line 920, in _ssl_wrap_socket_and_match_hostname
    ssl_sock = ssl_wrap_socket(
        sock=sock,
    ...<8 lines>...
        tls_in_tls=tls_in_tls,
    )
  File "/Users/shekspii/Desktop/OOP_Global/labs/lb_2_OOP/projectX/myenv/lib/python3.13/site-packages/urllib3/util/ssl_.py", line 460, in ssl_wrap_socket
    ssl_sock = _ssl_wrap_socket_impl(sock, context, tls_in_tls, server_hostname)
  File "/Users/shekspii/Desktop/OOP_Global/labs/lb_2_OOP/projectX/myenv/lib/python3.13/site-packages/urllib3/util/ssl_.py", line 504, in _ssl_wrap_socket_impl
    return ssl_context.wrap_socket(sock, server_hostname=server_hostname)
           ~~~~~~~~~~~~~~~~~~~~~~~^^^^^^^^^^^^^^^^^^^^^^^^^^^^^^^^^^^^^^^
  File "/opt/homebrew/Cellar/python@3.13/3.13.2/Frameworks/Python.framework/Versions/3.13/lib/python3.13/ssl.py", line 455, in wrap_socket
    return self.sslsocket_class._create(
           ~~~~~~~~~~~~~~~~~~~~~~~~~~~~^
        sock=sock,
        ^^^^^^^^^^
    ...<5 lines>...
        session=session
        ^^^^^^^^^^^^^^^
    )
    ^
  File "/opt/homebrew/Cellar/python@3.13/3.13.2/Frameworks/Python.framework/Versions/3.13/lib/python3.13/ssl.py", line 1076, in _create
    self.do_handshake()
    ~~~~~~~~~~~~~~~~~^^
  File "/opt/homebrew/Cellar/python@3.13/3.13.2/Frameworks/Python.framework/Versions/3.13/lib/python3.13/ssl.py", line 1372, in do_handshake
    self._sslobj.do_handshake()
    ~~~~~~~~~~~~~~~~~~~~~~~~~^^
TimeoutError: _ssl.c:1011: The handshake operation timed out

The above exception was the direct cause of the following exception:

Traceback (most recent call last):
  File "/Users/shekspii/Desktop/OOP_Global/labs/lb_2_OOP/projectX/myenv/lib/python3.13/site-packages/requests/adapters.py", line 667, in send
    resp = conn.urlopen(
        method=request.method,
    ...<9 lines>...
        chunked=chunked,
    )
  File "/Users/shekspii/Desktop/OOP_Global/labs/lb_2_OOP/projectX/myenv/lib/python3.13/site-packages/urllib3/connectionpool.py", line 841, in urlopen
    retries = retries.increment(
        method, url, error=new_e, _pool=self, _stacktrace=sys.exc_info()[2]
    )
  File "/Users/shekspii/Desktop/OOP_Global/labs/lb_2_OOP/projectX/myenv/lib/python3.13/site-packages/urllib3/util/retry.py", line 474, in increment
    raise reraise(type(error), error, _stacktrace)
          ~~~~~~~^^^^^^^^^^^^^^^^^^^^^^^^^^^^^^^^^
  File "/Users/shekspii/Desktop/OOP_Global/labs/lb_2_OOP/projectX/myenv/lib/python3.13/site-packages/urllib3/util/util.py", line 39, in reraise
    raise value
  File "/Users/shekspii/Desktop/OOP_Global/labs/lb_2_OOP/projectX/myenv/lib/python3.13/site-packages/urllib3/connectionpool.py", line 787, in urlopen
    response = self._make_request(
        conn,
    ...<10 lines>...
        **response_kw,
    )
  File "/Users/shekspii/Desktop/OOP_Global/labs/lb_2_OOP/projectX/myenv/lib/python3.13/site-packages/urllib3/connectionpool.py", line 488, in _make_request
    raise new_e
  File "/Users/shekspii/Desktop/OOP_Global/labs/lb_2_OOP/projectX/myenv/lib/python3.13/site-packages/urllib3/connectionpool.py", line 466, in _make_request
    self._raise_timeout(err=e, url=url, timeout_value=conn.timeout)
    ~~~~~~~~~~~~~~~~~~~^^^^^^^^^^^^^^^^^^^^^^^^^^^^^^^^^^^^^^^^^^^^
  File "/Users/shekspii/Desktop/OOP_Global/labs/lb_2_OOP/projectX/myenv/lib/python3.13/site-packages/urllib3/connectionpool.py", line 367, in _raise_timeout
    raise ReadTimeoutError(
        self, url, f"Read timed out. (read timeout={timeout_value})"
    ) from err
urllib3.exceptions.ReadTimeoutError: HTTPSConnectionPool(host='api.telegram.org', port=443): Read timed out. (read timeout=20)

During handling of the above exception, another exception occurred:

Traceback (most recent call last):
  File "/Users/shekspii/Desktop/OOP_Global/labs/lb_2_OOP/projectX/myenv/lib/python3.13/site-packages/telebot/__init__.py", line 1110, in infinity_polling
    self.polling(non_stop=True, timeout=timeout, long_polling_timeout=long_polling_timeout,
    ~~~~~~~~~~~~^^^^^^^^^^^^^^^^^^^^^^^^^^^^^^^^^^^^^^^^^^^^^^^^^^^^^^^^^^^^^^^^^^^^^^^^^^^
                 logger_level=logger_level, allowed_updates=allowed_updates, restart_on_change=False,
                 ^^^^^^^^^^^^^^^^^^^^^^^^^^^^^^^^^^^^^^^^^^^^^^^^^^^^^^^^^^^^^^^^^^^^^^^^^^^^^^^^^^^^
                 *args, **kwargs)
                 ^^^^^^^^^^^^^^^^
  File "/Users/shekspii/Desktop/OOP_Global/labs/lb_2_OOP/projectX/myenv/lib/python3.13/site-packages/telebot/__init__.py", line 1198, in polling
    self.__threaded_polling(non_stop=non_stop, interval=interval, timeout=timeout, long_polling_timeout=long_polling_timeout,
    ~~~~~~~~~~~~~~~~~~~~~~~^^^^^^^^^^^^^^^^^^^^^^^^^^^^^^^^^^^^^^^^^^^^^^^^^^^^^^^^^^^^^^^^^^^^^^^^^^^^^^^^^^^^^^^^^^^^^^^^^^
                            logger_level=logger_level, allowed_updates=allowed_updates)
                            ^^^^^^^^^^^^^^^^^^^^^^^^^^^^^^^^^^^^^^^^^^^^^^^^^^^^^^^^^^^
  File "/Users/shekspii/Desktop/OOP_Global/labs/lb_2_OOP/projectX/myenv/lib/python3.13/site-packages/telebot/__init__.py", line 1273, in __threaded_polling
    raise e
  File "/Users/shekspii/Desktop/OOP_Global/labs/lb_2_OOP/projectX/myenv/lib/python3.13/site-packages/telebot/__init__.py", line 1234, in __threaded_polling
    polling_thread.raise_exceptions()
    ~~~~~~~~~~~~~~~~~~~~~~~~~~~~~~~^^
  File "/Users/shekspii/Desktop/OOP_Global/labs/lb_2_OOP/projectX/myenv/lib/python3.13/site-packages/telebot/util.py", line 111, in raise_exceptions
    raise self.exception_info
  File "/Users/shekspii/Desktop/OOP_Global/labs/lb_2_OOP/projectX/myenv/lib/python3.13/site-packages/telebot/util.py", line 93, in run
    task(*args, **kwargs)
    ~~~~^^^^^^^^^^^^^^^^^
  File "/Users/shekspii/Desktop/OOP_Global/labs/lb_2_OOP/projectX/myenv/lib/python3.13/site-packages/telebot/__init__.py", line 688, in __retrieve_updates
    updates = self.get_updates(offset=(self.last_update_id + 1),
                               allowed_updates=allowed_updates,
                               timeout=timeout, long_polling_timeout=long_polling_timeout)
  File "/Users/shekspii/Desktop/OOP_Global/labs/lb_2_OOP/projectX/myenv/lib/python3.13/site-packages/telebot/__init__.py", line 660, in get_updates
    json_updates = apihelper.get_updates(
        self.token, offset=offset, limit=limit, timeout=timeout, allowed_updates=allowed_updates,
        long_polling_timeout=long_polling_timeout)
  File "/Users/shekspii/Desktop/OOP_Global/labs/lb_2_OOP/projectX/myenv/lib/python3.13/site-packages/telebot/apihelper.py", line 332, in get_updates
    return _make_request(token, method_url, params=payload)
  File "/Users/shekspii/Desktop/OOP_Global/labs/lb_2_OOP/projectX/myenv/lib/python3.13/site-packages/telebot/apihelper.py", line 162, in _make_request
    result = _get_req_session().request(
        method, request_url, params=params, files=files,
        timeout=(connect_timeout, read_timeout), proxies=proxy)
  File "/Users/shekspii/Desktop/OOP_Global/labs/lb_2_OOP/projectX/myenv/lib/python3.13/site-packages/requests/sessions.py", line 589, in request
    resp = self.send(prep, **send_kwargs)
  File "/Users/shekspii/Desktop/OOP_Global/labs/lb_2_OOP/projectX/myenv/lib/python3.13/site-packages/requests/sessions.py", line 703, in send
    r = adapter.send(request, **kwargs)
  File "/Users/shekspii/Desktop/OOP_Global/labs/lb_2_OOP/projectX/myenv/lib/python3.13/site-packages/requests/adapters.py", line 713, in send
    raise ReadTimeout(e, request=request)
requests.exceptions.ReadTimeout: HTTPSConnectionPool(host='api.telegram.org', port=443): Read timed out. (read timeout=20)

2025-04-29 16:17:23,791 - INFO - Мероприятие 22 обновлено пользователем green_ruff
2025-04-29 16:17:59,171 - ERROR - Infinity polling: polling exited
2025-04-29 16:17:59,171 - ERROR - Break infinity polling
2025-04-29 16:18:48,527 - INFO - Удалено мероприятие 21 пользователем green_ruff
2025-04-29 16:18:56,059 - ERROR - Infinity polling: polling exited
2025-04-29 16:18:56,059 - ERROR - Break infinity polling
2025-05-02 10:40:55,557 - INFO - Уведомление отправлено пользователю 1230795197 о событии Спервомаем, дорогая
2025-05-02 10:41:01,312 - ERROR - Infinity polling: polling exited
2025-05-02 10:41:01,312 - ERROR - Break infinity polling
2025-05-02 10:43:16,598 - INFO - Уведомление отправлено пользователю 1230795197 о событии Спервомаем, дорогая
2025-05-02 10:44:00,269 - INFO - Пользователем 1230795197 было создано мероприятие Мероприятие 27
2025-05-02 10:44:17,016 - INFO - Уведомление отправлено пользователю 1230795197 о событии Мeроприятие 26
2025-05-02 10:44:17,185 - INFO - Уведомление отправлено пользователю 1230795197 о событии Мероприятие 27
2025-05-02 10:44:59,955 - ERROR - Infinity polling: polling exited
2025-05-02 10:44:59,955 - ERROR - Break infinity polling
2025-05-04 17:57:58,395 - ERROR - Infinity polling: polling exited
2025-05-04 17:57:58,395 - ERROR - Break infinity polling
